2022-07-22 01:10:30,814 INFO    Thread-1157:44144 [wandb_setup.py:_flush():76] Configure stats pid to 44144
2022-07-22 01:10:30,814 INFO    Thread-1157:44144 [wandb_setup.py:_flush():76] Loading settings from /Users/ilgeehong/.config/wandb/settings
2022-07-22 01:10:30,815 INFO    Thread-1157:44144 [wandb_setup.py:_flush():76] Loading settings from wandb/settings
2022-07-22 01:10:30,815 INFO    Thread-1157:44144 [wandb_setup.py:_flush():76] Loading settings from environment variables: {'project': 'contrastive-learning-on-graphs', 'entity': 'graphs-stats-and-ml', 'root_dir': '/Users/ilgeehong/Desktop/SemGCon/Ours', 'run_id': '6j1iww8w', 'sweep_param_path': '/Users/ilgeehong/Desktop/SemGCon/Ours/wandb/sweep-d413brmc/config-6j1iww8w.yaml', 'sweep_id': 'd413brmc'}
2022-07-22 01:10:30,815 INFO    Thread-1157:44144 [wandb_setup.py:_flush():76] Inferring run settings from compute environment: {'program_relpath': 'hyperparameter.py', 'program': '/Users/ilgeehong/Desktop/SemGCon/Ours/hyperparameter.py'}
2022-07-22 01:10:30,815 INFO    Thread-1157:44144 [wandb_init.py:_log_setup():461] Logging user logs to /Users/ilgeehong/Desktop/SemGCon/Ours/wandb/run-20220722_011030-6j1iww8w/logs/debug.log
2022-07-22 01:10:30,815 INFO    Thread-1157:44144 [wandb_init.py:_log_setup():462] Logging internal logs to /Users/ilgeehong/Desktop/SemGCon/Ours/wandb/run-20220722_011030-6j1iww8w/logs/debug-internal.log
2022-07-22 01:10:30,815 INFO    Thread-1157:44144 [wandb_init.py:init():495] calling init triggers
2022-07-22 01:10:30,815 INFO    Thread-1157:44144 [wandb_init.py:init():498] wandb.init called with sweep_config: {'channels': 128, 'dataset': 'Cora', 'edr': 0, 'epochs': 20, 'fmr': 0, 'lr1': 0.0005, 'lr2': 0.005, 'n_experiments': 1, 'n_layers': 1, 'split': 'PublicSplit', 'tau': 0.9, 'wd1': 0.001, 'wd2': 0.0001}
config: {'method': 'grid', 'metric': {'goal': 'minimize', 'name': 'best_val_loss'}, 'parameters': {'channels': {'values': [128, 256, 512, 1024]}, 'dataset': {'values': ['Cora']}, 'edr': {'values': [0, 0.1, 0.2, 0.3, 0.4, 0.5]}, 'epochs': {'values': [20, 50, 100, 150, 200]}, 'fmr': {'values': [0, 0.1, 0.2, 0.3, 0.4, 0.5]}, 'lr1': {'values': [0.0005, 0.001, 0.005, 0.01]}, 'lr2': {'values': [0.001, 0.005, 0.01]}, 'n_experiments': {'values': [1]}, 'n_layers': {'values': [1, 2, 3]}, 'split': {'values': ['PublicSplit']}, 'tau': {'values': [0.1, 0.3, 0.5, 0.7, 0.9]}, 'wd1': {'values': [0.0005, 0.001, 0.005, 0.01]}, 'wd2': {'values': [0.0001, 0.001, 0.01]}}}
2022-07-22 01:10:30,815 INFO    Thread-1157:44144 [wandb_init.py:init():548] starting backend
2022-07-22 01:10:30,815 INFO    Thread-1157:44144 [backend.py:_multiprocessing_setup():97] multiprocessing start_methods=spawn,fork,forkserver, using: spawn
2022-07-22 01:10:30,830 ERROR   Thread-1157:44144 [wandb_init.py:init():1070] error
Traceback (most recent call last):
  File "/Library/Frameworks/Python.framework/Versions/3.9/lib/python3.9/site-packages/wandb/sdk/wandb_init.py", line 1043, in init
  File "/Library/Frameworks/Python.framework/Versions/3.9/lib/python3.9/site-packages/wandb/sdk/wandb_init.py", line 556, in init
  File "/Library/Frameworks/Python.framework/Versions/3.9/lib/python3.9/site-packages/wandb/sdk/backend/backend.py", line 187, in ensure_launched
  File "/Library/Frameworks/Python.framework/Versions/3.9/lib/python3.9/multiprocessing/context.py", line 103, in Queue
  File "/Library/Frameworks/Python.framework/Versions/3.9/lib/python3.9/multiprocessing/queues.py", line 49, in __init__
  File "/Library/Frameworks/Python.framework/Versions/3.9/lib/python3.9/multiprocessing/context.py", line 88, in BoundedSemaphore
  File "/Library/Frameworks/Python.framework/Versions/3.9/lib/python3.9/multiprocessing/synchronize.py", line 145, in __init__
  File "/Library/Frameworks/Python.framework/Versions/3.9/lib/python3.9/multiprocessing/synchronize.py", line 57, in __init__
OSError: [Errno 24] Too many open files
2022-07-22 01:10:32,836 ERROR   MainThread:44144 [pyagent.py:_run_jobs_from_queue():228] Run 6j1iww8w errored: Exception('problem')
2022-07-22 01:10:39,188 ERROR   Thread-1  :44144 [retry.py:__call__():132] Retry attempt failed:
Traceback (most recent call last):
  File "/Library/Frameworks/Python.framework/Versions/3.9/lib/python3.9/site-packages/urllib3/connection.py", line 174, in _new_conn
  File "/Library/Frameworks/Python.framework/Versions/3.9/lib/python3.9/site-packages/urllib3/util/connection.py", line 72, in create_connection
  File "/Library/Frameworks/Python.framework/Versions/3.9/lib/python3.9/socket.py", line 953, in getaddrinfo
socket.gaierror: [Errno 8] nodename nor servname provided, or not known

During handling of the above exception, another exception occurred:

Traceback (most recent call last):
  File "/Library/Frameworks/Python.framework/Versions/3.9/lib/python3.9/site-packages/urllib3/connectionpool.py", line 703, in urlopen
  File "/Library/Frameworks/Python.framework/Versions/3.9/lib/python3.9/site-packages/urllib3/connectionpool.py", line 386, in _make_request
  File "/Library/Frameworks/Python.framework/Versions/3.9/lib/python3.9/site-packages/urllib3/connectionpool.py", line 1040, in _validate_conn
  File "/Library/Frameworks/Python.framework/Versions/3.9/lib/python3.9/site-packages/urllib3/connection.py", line 358, in connect
  File "/Library/Frameworks/Python.framework/Versions/3.9/lib/python3.9/site-packages/urllib3/connection.py", line 186, in _new_conn
urllib3.exceptions.NewConnectionError: <urllib3.connection.HTTPSConnection object at 0x7ff613055be0>: Failed to establish a new connection: [Errno 8] nodename nor servname provided, or not known

During handling of the above exception, another exception occurred:

Traceback (most recent call last):
  File "/Library/Frameworks/Python.framework/Versions/3.9/lib/python3.9/site-packages/requests/adapters.py", line 440, in send
  File "/Library/Frameworks/Python.framework/Versions/3.9/lib/python3.9/site-packages/urllib3/connectionpool.py", line 785, in urlopen
  File "/Library/Frameworks/Python.framework/Versions/3.9/lib/python3.9/site-packages/urllib3/util/retry.py", line 592, in increment
urllib3.exceptions.MaxRetryError: HTTPSConnectionPool(host='api.wandb.ai', port=443): Max retries exceeded with url: /graphql (Caused by NewConnectionError('<urllib3.connection.HTTPSConnection object at 0x7ff613055be0>: Failed to establish a new connection: [Errno 8] nodename nor servname provided, or not known'))

During handling of the above exception, another exception occurred:

Traceback (most recent call last):
  File "/Library/Frameworks/Python.framework/Versions/3.9/lib/python3.9/site-packages/wandb/sdk/lib/retry.py", line 108, in __call__
  File "/Library/Frameworks/Python.framework/Versions/3.9/lib/python3.9/site-packages/wandb/sdk/internal/internal_api.py", line 158, in execute
  File "/Library/Frameworks/Python.framework/Versions/3.9/lib/python3.9/site-packages/wandb/vendor/gql-0.2.0/wandb_gql/client.py", line 52, in execute
  File "/Library/Frameworks/Python.framework/Versions/3.9/lib/python3.9/site-packages/wandb/vendor/gql-0.2.0/wandb_gql/client.py", line 60, in _get_result
  File "/Library/Frameworks/Python.framework/Versions/3.9/lib/python3.9/site-packages/wandb/vendor/gql-0.2.0/wandb_gql/transport/requests.py", line 38, in execute
  File "/Library/Frameworks/Python.framework/Versions/3.9/lib/python3.9/site-packages/requests/api.py", line 117, in post
  File "/Library/Frameworks/Python.framework/Versions/3.9/lib/python3.9/site-packages/requests/api.py", line 61, in request
  File "/Library/Frameworks/Python.framework/Versions/3.9/lib/python3.9/site-packages/requests/sessions.py", line 529, in request
  File "/Library/Frameworks/Python.framework/Versions/3.9/lib/python3.9/site-packages/requests/sessions.py", line 645, in send
  File "/Library/Frameworks/Python.framework/Versions/3.9/lib/python3.9/site-packages/requests/adapters.py", line 519, in send
requests.exceptions.ConnectionError: HTTPSConnectionPool(host='api.wandb.ai', port=443): Max retries exceeded with url: /graphql (Caused by NewConnectionError('<urllib3.connection.HTTPSConnection object at 0x7ff613055be0>: Failed to establish a new connection: [Errno 8] nodename nor servname provided, or not known'))
